{
    "cve": {
        "data_type": "CVE",
        "data_format": "MITRE",
        "data_version": "4.0",
        "CVE_data_meta": {
            "ID": "CVE-2020-13596",
            "ASSIGNER": "cve@mitre.org"
        },
        "problemtype": {
            "problemtype_data": [
                {
                    "description": []
                }
            ]
        },
        "references": {
            "reference_data": [
                {
                    "url": "https://docs.djangoproject.com/en/3.0/releases/security/",
                    "name": "https://docs.djangoproject.com/en/3.0/releases/security/",
                    "refsource": "MISC",
                    "tags": []
                },
                {
                    "url": "https://groups.google.com/forum/#!msg/django-announce/pPEmb2ot4Fo/X-SMalYSBAAJ",
                    "name": "https://groups.google.com/forum/#!msg/django-announce/pPEmb2ot4Fo/X-SMalYSBAAJ",
                    "refsource": "MISC",
                    "tags": []
                },
                {
                    "url": "https://www.djangoproject.com/weblog/2020/jun/03/security-releases/",
                    "name": "https://www.djangoproject.com/weblog/2020/jun/03/security-releases/",
                    "refsource": "CONFIRM",
                    "tags": []
                }
            ]
        },
        "description": {
            "description_data": [
                {
                    "lang": "en",
                    "value": "An issue was discovered in Django 2.2 before 2.2.13 and 3.0 before 3.0.7. Query parameters generated by the Django admin ForeignKeyRawIdWidget were not properly URL encoded, leading to a possibility of an XSS attack."
                }
            ]
        }
    },
    "configurations": {
        "CVE_data_version": "4.0",
        "nodes": []
    },
    "impact": {},
    "publishedDate": "2020-06-03T14:15Z",
    "lastModifiedDate": "2020-06-03T14:25Z"
}