{
    "cve": {
        "data_type": "CVE",
        "data_format": "MITRE",
        "data_version": "4.0",
        "CVE_data_meta": {
            "ID": "CVE-2020-15801",
            "ASSIGNER": "cve@mitre.org"
        },
        "problemtype": {
            "problemtype_data": [
                {
                    "description": []
                }
            ]
        },
        "references": {
            "reference_data": [
                {
                    "url": "https://bugs.python.org/issue41304",
                    "name": "https://bugs.python.org/issue41304",
                    "refsource": "MISC",
                    "tags": []
                },
                {
                    "url": "https://github.com/python/cpython/pull/21495",
                    "name": "https://github.com/python/cpython/pull/21495",
                    "refsource": "MISC",
                    "tags": []
                }
            ]
        },
        "description": {
            "description_data": [
                {
                    "lang": "en",
                    "value": "In Python 3.8.4, sys.path restrictions specified in a python38._pth file are ignored, allowing code to be loaded from arbitrary locations. The <executable-name>._pth file (e.g., the python._pth file) is not affected."
                }
            ]
        }
    },
    "configurations": {
        "CVE_data_version": "4.0",
        "nodes": []
    },
    "impact": {},
    "publishedDate": "2020-07-17T03:15Z",
    "lastModifiedDate": "2020-07-17T03:15Z"
}