{
    "cve": {
        "data_type": "CVE",
        "data_format": "MITRE",
        "data_version": "4.0",
        "CVE_data_meta": {
            "ID": "CVE-2019-20907",
            "ASSIGNER": "cve@mitre.org"
        },
        "problemtype": {
            "problemtype_data": [
                {
                    "description": []
                }
            ]
        },
        "references": {
            "reference_data": [
                {
                    "url": "https://bugs.python.org/issue39017",
                    "name": "https://bugs.python.org/issue39017",
                    "refsource": "CONFIRM",
                    "tags": []
                },
                {
                    "url": "https://github.com/python/cpython/pull/21454",
                    "name": "https://github.com/python/cpython/pull/21454",
                    "refsource": "CONFIRM",
                    "tags": []
                }
            ]
        },
        "description": {
            "description_data": [
                {
                    "lang": "en",
                    "value": "In Lib/tarfile.py in Python through 3.8.3, an attacker is able to craft a TAR archive leading to an infinite loop when opened by tarfile.open, because _proc_pax lacks header validation."
                }
            ]
        }
    },
    "configurations": {
        "CVE_data_version": "4.0",
        "nodes": []
    },
    "impact": {},
    "publishedDate": "2020-07-13T13:15Z",
    "lastModifiedDate": "2020-07-13T13:15Z"
}